Workbook

Sheet raw_data
A1: Raw sockeye salmon counts; includes all count types, all maturity types.
H3: =(SUM(B16:F16,H16:AI16)*SUM(G17:G120,G7:G15))/SUM(B7:F120,H7:AI120,G7:G15,G17:G120) -> 0.053746436
A4: DAILY:
A5: Date | B5: 1988 | C5: 1989 | D5: 1990 | E5: 1991 | F5: 1992 | G5: 1993 | H5: 1994 | I5: 1995 | J5: 1996 | K5: 1997 | L5: 1998 | M5: 1999 | N5: 2000 | O5: 2001 | P5: 2002 | Q5: 2003 | R5: 2004 | S5: 2005 | T5: 2006 | U5: 2007 | V5: 2008 | W5: 2009 | X5: 2010 | Y5: 2011 | Z5: 2012 | AA5: 2013 | AB5: 2014 | AC5: 2015 | AD5: 2016 | AE5: 2017 | AF5: 2018 | AG5: 2019 | AH5: 2020 | AI5: 2021
A6: 121 | Q6: 0 | S6: 0 | T6: 0
A7: 122 | F7: 0 | O7: 0 | Q7: 0 | S7: 0 | T7: 0 | AD7: 0 | AI7: 0
A8: 123 | F8: 0 | O8: 0 | Q8: 0 | S8: 0 | T8: 0 | AD8: 0 | AI8: 0
A9: 124 | F9: 0 | L9: 0 | O9: 0 | Q9: 0 | S9: 0 | T9: 0 | AD9: 0 | AI9: 0
A10: 125 | F10: 0 | K10: 0 | L10: 0 | O10: 0 | Q10: 0 | S10: 0 | T10: 0 | AD10: 0 | AG10: 0 | AI10: 0
A11: 126 | F11: 0 | K11: 0 | L11: 0 | O11: 0 | Q11: 0 | S11: 0 | T11: 0 | Y11: 0 | AB11: 0 | AD11: 0 | AE11: 0 | AG11: 0 | AI11: 0
A12: 127 | F12: 0 | J12: 0 | K12: 0 | L12: 0 | O12: 0 | Q12: 0 | S12: 0 | T12: 0 | Y12: 0 | AB12: 0 | AC12: 0 | AD12: 0 | AE12: 0 | AG12: 0 | AI12: 0
A13: 128 | D13: 0 | F13: 0 | I13: 0 | J13: 0 | K13: 0 | L13: 0 | O13: 0 | Q13: 0 | S13: 0 | T13: 0 | X13: 0 | Y13: 0 | AB13: 0 | AC13: 0 | AD13: 0 | AE13: 0 | AG13: 0 | AI13: 0
A14: 129 | D14: 0 | E14: 0 | F14: 0 | I14: 0 | J14: 0 | K14: 0 | L14: 0 | M14: 0 | N14: 0 | O14: 0 | Q14: 0 | R14: 0 | S14: 0 | T14: 0 | W14: 0 | X14: 0 | Y14: 0 | AB14: 0 | AC14: 0 | AD14: 0 | AE14: 0 | AG14: 0 | AI14: 0
A15: 130 | D15: 0 | E15: 0 | F15: 0 | I15: 0 | J15: 0 | K15: 0 | L15: 0 | M15: 0 | N15: 0 | O15: 0 | P15: 0 | Q15: 0 | R15: 0 | S15: 0 | T15: 0 | U15: 0 | W15: 0 | X15: 0 | Y15: 0 | AB15: 1 | AC15: 0 | AD15: 0 | AE15: 0 | AG15: 0 | AI15: 0 | AJ15: =SUM(B15:AI15)/SUM(B120:AI120) -> 4.3267136e-07
A16: 131 | D16: 0 | E16: 0 | F16: 0 | I16: 0 | J16: 0 | K16: 0 | L16: 0 | M16: 0 | N16: 0 | O16: 0 | P16: 0 | Q16: 0 | R16: 0 | S16: 0 | T16: 0 | U16: 0 | V16: 0 | W16: 0 | X16: 0 | Y16: 0 | AB16: 2 | AC16: 0 | AD16: 0 | AE16: 0 | AG16: 0 | AI16: 0
A17: 132 | D17: 0 | E17: 0 | F17: 0 | I17: 0 | J17: 0 | K17: 0 | L17: 0 | M17: 0 | N17: 0 | O17: 0 | P17: 0 | Q17: 0 | R17: 0 | S17: 0 | T17: 0 | U17: 0 | V17: 0 | W17: 0 | X17: 0 | Y17: 0 | AB17: 1 | AC17: 0 | AD17: 0 | AE17: 0 | AG17: 0 | AI17: 0
A18: 133 | D18: 0 | E18: 0 | F18: 0 | I18: 0 | J18: 0 | K18: 0 | L18: 0 | M18: 0 | N18: 0 | O18: 0 | P18: 0 | Q18: 0 | R18: 0 | S18: 0 | T18: 0 | U18: 0 | V18: 0 | W18: 0 | X18: 0 | Y18: 0 | AB18: 0 | AC18: 0 | AD18: 0 | AE18: 0 | AG18: 0 | AI18: 0
A19: 134 | D19: 0 | E19: 0 | F19: 0 | I19: 0 | J19: 0 | K19: 0 | L19: 0 | M19: 0 | N19: 0 | O19: 0 | P19: 0 | Q19: 0 | R19: 0 | S19: 0 | T19: 0 | U19: 0 | V19: 0 | W19: 0 | X19: 0 | Y19: 0 | AB19: 1 | AC19: 0 | AD19: 0 | AE19: 0 | AG19: 0 | AH19: 0 | AI19: 0
A20: 135 | D20: 0 | E20: 0 | F20: 0 | I20: 0 | J20: 0 | K20: 0 | L20: 0 | M20: 0 | N20: 0 | O20: 0 | P20: 0 | Q20: 0 | R20: 0 | S20: 0 | T20: 0 | U20: 0 | V20: 0 | W20: 0 | X20: 0 | Y20: 3 | AB20: 0 | AC20: 0 | AD20: 0 | AE20: 0 | AG20: 0 | AH20: 0 | AI20: 0
A21: 136 | D21: 0 | E21: 0 | F21: 0 | I21: 0 | J21: 0 | K21: 0 | L21: 0 | M21: 0 | N21: 0 | O21: 0 | P21: 0 | Q21: 0 | R21: 0 | S21: 0 | T21: 0 | U21: 0 | V21: 0 | W21: 5 | X21: 0 | Y21: 0 | AB21: 0 | AC21: 0 | AD21: 0 | AE21: 0 | AG21: 0 | AH21: 0 | AI21: 0
A22: 137 | D22: 0 | E22: 0 | F22: 0 | I22: 0 | J22: 0 | K22: 0 | L22: 0 | M22: 0 | N22: 0 | O22: 0 | P22: 0 | Q22: 0 | R22: 0 | S22: 0 | T22: 0 | U22: 0 | V22: 0 | W22: 0 | X22: 0 | Y22: 0 | AB22: 2 | AC22: 0 | AD22: 0 | AE22: 0 | AG22: 0 | AH22: 0 | AI22: 0
A23: 138 | D23: 0 | E23: 0 | F23: 0 | I23: 0 | J23: 0 | K23: 0 | L23: 0 | M23: 0 | N23: 0 | O23: 0 | P23: 0 | Q23: 0 | R23: 0 | S23: 0 | T23: 0 | U23: 0 | V23: 0 | W23: 0 | X23: 0 | Y23: 0 | AB23: 0 | AC23: 0 | AD23: 0 | AE23: 0 | AG23: 0 | AH23: 0 | AI23: 0
A24: 139 | D24: 0 | E24: 0 | F24: 0 | I24: 0 | J24: 0 | K24: 0 | L24: 0 | M24: 0 | N24: 0 | O24: 0 | P24: 0 | Q24: 0 | R24: 0 | S24: 0 | T24: 0 | U24: 0 | V24: 0 | W24: 0 | X24: 0 | Y24: 0 | Z24: 0 | AB24: 0 | AC24: 0 | AD24: 0 | AE24: 0 | AG24: 0 | AH24: 0 | AI24: 0
A25: 140 | D25: 0 | E25: 0 | F25: 0 | I25: 0 | J25: 0 | K25: 0 | L25: 0 | M25: 0 | N25: 0 | O25: 0 | P25: 0 | Q25: 0 | R25: 0 | S25: 0 | T25: 0 | U25: 0 | V25: 0 | W25: 0 | X25: 0 | Y25: 0 | Z25: 0 | AB25: 0 | AC25: 0 | AD25: 1 | AE25: 0 | AG25: 0 | AH25: 0 | AI25: 0
A26: 141 | D26: 0 | E26: 0 | F26: 0 | H26: 0 | I26: 0 | J26: 0 | K26: 0 | L26: 0 | M26: 0 | N26: 0 | O26: 0 | P26: 0 | Q26: 0 | R26: 0 | S26: 0 | T26: 0 | U26: 0 | V26: 0 | W26: 0 | X26: 0 | Y26: 0 | Z26: 0 | AB26: 4 | AC26: 0 | AD26: 0 | AE26: 0 | AG26: 0 | AH26: 0 | AI26: 0
A27: 142 | D27: 0 | E27: 0 | F27: 0 | H27: 0 | I27: 0 | J27: 0 | K27: 0 | L27: 0 | M27: 0 | N27: 0 | O27: 0 | P27: 0 | Q27: 0 | R27: 0 | S27: 0 | T27: 0 | U27: 0 | V27: 0 | W27: 0 | X27: 0 | Y27: 0 | Z27: 0 | AB27: 0 | AC27: 2 | AD27: 0 | AE27: 0 | AG27: 0 | AH27: 0 | AI27: 0
A28: 143 | D28: 0 | E28: 0 | F28: 0 | H28: 0 | I28: 0 | J28: 0 | K28: 0 | L28: 0 | M28: 0 | N28: 0 | O28: 0 | P28: 0 | Q28: 0 | R28: 0 | S28: 0 | T28: 0 | U28: 0 | V28: 0 | W28: 0 | X28: 0 | Y28: 0 | Z28: 0 | AA28: 0 | AB28: 0 | AC28: 0 | AD28: 0 | AE28: 0 | AF28: 0 | AG28: 0 | AH28: 0 | AI28: 0
A29: 144 | D29: 0 | E29: 0 | F29: 0 | H29: 0 | I29: 0 | J29: 0 | K29: 0 | L29: 0 | M29: 0 | N29: 0 | O29: 0 | P29: 0 | Q29: 0 | R29: 0 | S29: 0 | T29: 0 | U29: 0 | V29: 0 | W29: 0 | X29: 0 | Y29: 0 | Z29: 0 | AA29: 0 | AB29: 0 | AC29: 1 | AD29: 0 | AE29: 0 | AF29: 0 | AG29: 0 | AH29: 0 | AI29: 0
A30: 145 | D30: 0 | E30: 0 | F30: 0 | H30: 0 | I30: 0 | J30: 0 | K30: 0 | L30: 3 | M30: 0 | N30: 0 | O30: 3 | P30: 0 | Q30: 0 | R30: 0 | S30: 154 | T30: 0 | U30: 0 | V30: 0 | W30: 0 | X30: 0 | Y30: 0 | Z30: 0 | AA30: 0 | AB30: 0 | AC30: 0 | AD30: 0 | AE30: 3 | AF30: 0 | AG30: 0 | AH30: 0 | AI30: 0
A31: 146 | C31: 0 | D31: 0 | E31: 0 | F31: 0 | H31: 0 | I31: 0 | J31: 0 | K31: 0 | L31: 8 | M31: 0 | N31: 0 | O31: 2 | P31: 0 | Q31: 0 | R31: 0 | S31: 57 | T31: 0 | U31: 0 | V31: 0 | W31: 0 | X31: 0 | Y31: 0 | Z31: 0 | AA31: 5 | AB31: 0 | AC31: 3 | AD31: 0 | AE31: 91 | AF31: 0 | AG31: 0 | AH31: 0 | AI31: 0
A32: 147 | C32: 0 | D32: 0 | E32: 0 | F32: 0 | H32: 0 | I32: 0 | J32: 0 | K32: 0 | L32: 0 | M32: 0 | N32: 0 | O32: 11 | P32: 2 | Q32: 3 | R32: 0 | S32: 1028 | T32: 0 | U32: 0 | V32: 0 | W32: 0 | X32: 0 | Y32: 3 | Z32: 0 | AA32: 0 | AB32: 0 | AC32: 8 | AD32: 0 | AE32: 19 | AF32: 0 | AG32: 0 | AH32: 0 | AI32: 0
A33: 148 | C33: 0 | D33: 0 | E33: 0 | F33: 0 | H33: 0 | I33: 1 | J33: 0 | K33: 0 | L33: 0 | M33: 0 | N33: 0 | O33: 0 | P33: 2 | Q33: 9 | R33: 0 | S33: 101 | T33: 0 | U33: 0 | V33: 0 | W33: 0 | X33: 0 | Y33: 7 | Z33: 0 | AA33: 0 | AB33: 1 | AC33: 5 | AD33: 0 | AE33: 201 | AF33: 0 | AG33: 0 | AH33: 0 | AI33: 5
A34: 149 | C34: 0 | D34: 0 | E34: 0 | F34: 4 | H34: 0 | I34: 0 | J34: 0 | K34: 0 | L34: 0 | M34: 0 | N34: 0 | O34: 6 | P34: 0 | Q34: 0 | R34: 0 | S34: 727 | T34: 0 | U34: 0 | V34: 0 | W34: 0 | X34: 1 | Y34: 0 | Z34: 0 | AA34: 11 | AB34: 0 | AC34: 3 | AD34: 0 | AE34: 1 | AF34: 0 | AG34: 0 | AH34: 0 | AI34: 0
A35: 150 | C35: 0 | D35: 0 | E35: 0 | F35: 5 | H35: 7 | I35: 2 | J35: 0 | K35: 0 | L35: 0 | M35: 0 | N35: 1 | O35: 13 | P35: 5 | Q35: 15 | R35: 3 | S35: 946 | T35: 0 | U35: 1 | V35: 0 | W35: 0 | X35: 0 | Y35: 0 | Z35: 0 | AA35: 425 | AB35: 0 | AC35: 3 | AD35: 0 | AE35: 7 | AF35: 1 | AG35: 0 | AH35: 0 | AI35: 0
A36: 151 | C36: 11 | D36: 0 | E36: 0 | F36: 14 | H36: 14 | I36: 0 | J36: 0 | K36: 0 | L36: 10 | M36: 0 | N36: 1 | O36: 0 | P36: 19 | Q36: 8 | R36: 4 | S36: 741 | T36: 0 | U36: 0 | V36: 0 | W36: 5 | X36: 0 | Y36: 5 | Z36: 1 | AA36: 68 | AB36: 0 | AC36: 1 | AD36: 0 | AE36: 69 | AF36: 0 | AG36: 0 | AH36: 0 | AI36: 0
A37: 152 | C37: 5 | D37: 5 | E37: 0 | F37: 2 | H37: 9 | I37: 0 | J37: 0 | K37: 197 | L37: 9 | M37: 0 | N37: 0 | O37: 172 | P37: 28 | Q37: 1 | R37: 0 | S37: 1072 | T37: 0 | U37: 0 | V37: 0 | W37: 1311 | X37: 0 | Y37: 81 | Z37: 1 | AA37: 38 | AB37: 0 | AC37: 2 | AD37: 0 | AE37: 1719 | AF37: 0 | AG37: 1 | AH37: 0 | AI37: 0
A38: 153 | C38: 6 | D38: 1 | E38: 0 | F38: 2 | H38: 17 | I38: 0 | J38: 0 | K38: 344 | L38: 23 | M38: 3 | N38: 0 | O38: 5 | P38: 57 | Q38: 300 | R38: 7 | S38: 688 | T38: 0 | U38: 3 | V38: 0 | W38: 826 | X38: 2 | Y38: 1 | Z38: 1 | AA38: 265 | AB38: 0 | AC38: 0 | AD38: 0 | AE38: 4312 | AF38: 0 | AG38: 6 | AH38: 0 | AI38: 0
A39: 154 | C39: 7 | D39: 8 | E39: 0 | F39: 4 | H39: 16 | I39: 0 | J39: 0 | K39: 198 | L39: 0 | M39: 3 | N39: 0 | O39: 11 | P39: 0 | Q39: 183 | R39: 22 | S39: 1266 | T39: 0 | U39: 4 | V39: 0 | W39: 368 | X39: 4 | Y39: 10 | Z39: 0 | AA39: 11 | AB39: 0 | AC39: 0 | AD39: 0 | AE39: 3435 | AF39: 2 | AG39: 0 | AH39: 1 | AI39: 0
A40: 155 | C40: 33 | D40: 4 | E40: 0 | F40: 6 | H40: 69 | I40: 11 | J40: 0 | K40: 0 | L40: 14 | M40: 1 | N40: 0 | O40: 0 | P40: 110 | Q40: 355 | R40: 0 | S40: 332 | T40: 0 | U40: 3 | V40: 0 | W40: 1370 | X40: 0 | Y40: 18 | Z40: 0 | AA40: 257 | AB40: 0 | AC40: 0 | AD40: 0 | AE40: 114 | AF40: 0 | AG40: 3 | AH40: 0 | AI40: 0
A41: 156 | C41: 77 | D41: 5 | E41: 0 | F41: 7 | H41: 40 | I41: 15 | J41: 0 | K41: 0 | L41: 21 | M41: 16 | N41: 4 | O41: 98 | P41: 126 | Q41: 7 | R41: 61 | S41: 1753 | T41: 0 | U41: 6 | V41: 0 | W41: 66 | X41: 25 | Y41: 4 | Z41: 0 | AA41: 1220 | AB41: 0 | AC41: 0 | AD41: 0 | AE41: 1429 | AF41: 0 | AG41: 1 | AH41: 0 | AI41: 0
...

Sheet global_missfill (Chilkat)
A1: Raw sockeye salmon counts; includes all count types, all maturity types.
A2: global missfill from R code | H2: Examples
A3: imputes all NAs in all years iteratively | H3: =(SUM(B104:F104)*SUM(F7:F153))/SUM(B7:F153) -> 3.2846524
A5: DAILY COUNTS:
A6: Date | B6: 2021 | C6: 2022 | D6: 2023 | E6: 2024 | F6: 2025
A7: 140
A8: 141
A9: 142
A10: 143
A11: 144
A12: 145
A13: 146
A14: 147
A15: 148
A16: 149
A17: 150
A18: 151
... A30: 163
A31: 164 | C31: 0 | E31: 0
A32: 165 | C32: 0 | E32: 0
A33: 166 | C33: 0 | E33: 0
A34: 167 | C34: 0 | D34: 0 | E34: 0
A35: 168 | C35: 0 | D35: 0 | E35: 0
A36: 169 | C36: 0 | D36: 0 | E36: 0
A37: 170 | C37: 0 | D37: 0 | E37: 0
A38: 171 | B38: 0 | C38: 0 | D38: 0 | E38: 0 | F38: 0
A39: 172 | B39: 0 | C39: 0 | D39: 0 | E39: 0 | F39: 0
A40: 173 | B40: 0 | C40: 0 | D40: 0 | E40: 0 | F40: 0
A41: 174 | B41: 0 | C41: 0 | D41: 0 | E41: 0 | F41: 0
A42: 175 | B42: 0 | C42: 0 | D42: 0 | E42: 0 | F42: 0
A43: 176 | B43: 0 | C43: 0 | D43: 0 | E43: 0 | F43: 0
A44: 177 | B44: 0 | C44: 0 | D44: 0 | E44: 0 | F44: 0
A45: 178 | B45: 0 | C45: 0 | D45: 0 | E45: 0 | F45: 0
A46: 179 | B46: 0 | C46: 0 | D46: 0 | E46: 0 | F46: 0
A47: 180 | B47: 0 | C47: 0 | D47: 0 | E47: 0 | F47: 0
A48: 181 | B48: 0 | C48: 0 | D48: 0 | E48: 0 | F48: 0
A49: 182 | B49: 0 | C49: 0 | D49: 0 | E49: 0 | F49: 0
... A153: 286 | B153: 118 | C153: 43.66709 | D153: 66.086999 | E153: 169.73853 | F153: 100.4327
A155: Subtotal | B155: =SUM(B7:B153) -> 8274 | C155: =SUM(C7:C149) -> 2749 | D155: =SUM(D7:D148) -> 4006 | E155: =SUM(E7:E151) -> 11471 | F155: =SUM(F7:F103,F117:F152) -> 6916
A156: Total | B156: =SUM(B39:B153) -> 8274 | C156: =SUM(C39:C149) -> 2749 | D156: =SUM(D39:D148) -> 4006 | E156: =SUM(E39:E151) -> 11471 | F156: =SUM(F39:F152) -> 6941.7719
...

Sheet global_missfill
A1: Raw sockeye salmon counts; includes all count types, all maturity types.
A2: global missfill from R code | H2: Examples
A3: imputes all NAs in all years iteratively | H3: =(SUM(B16:AI16)*SUM(G7:G120))/SUM(B7:AI120) -> 0.036883881 | I3: =(SUM(B92:AI92)*SUM(V7:V120))/SUM(B7:AI120) -> 493.90061
A5: DAILY COUNTS:
A6: Date | B6: 1988 | C6: 1989 | D6: 1990 | E6: 1991 | F6: 1992 | G6: 1993 | H6: 1994 | I6: 1995 | J6: 1996 | K6: 1997 | L6: 1998 | M6: 1999 | N6: 2000 | O6: 2001 | P6: 2002 | Q6: 2003 | R6: 2004 | S6: 2005 | T6: 2006 | U6: 2007 | V6: 2008 | W6: 2009 | X6: 2010 | Y6: 2011 | Z6: 2012 | AA6: 2013 | AB6: 2014 | AC6: 2015 | AD6: 2016 | AE6: 2017 | AF6: 2018 | AG6: 2019 | AH6: 2020 | AI6: 2021
A7: 121 | B7: 0 | C7: 0 | D7: 0 | E7: 0 | F7: 0 | G7: 0 | H7: 0 | I7: 0 | J7: 0 | K7: 0 | L7: 0 | M7: 0 | N7: 0 | O7: 0 | P7: 0 | Q7: 0 | R7: 0 | S7: 0 | T7: 0 | U7: 0 | V7: 0 | W7: 0 | X7: 0 | Y7: 0 | Z7: 0 | AA7: 0 | AB7: 0 | AC7: 0 | AD7: 0 | AE7: 0 | AF7: 0 | AG7: 0 | AH7: 0 | AI7: 0
A8: 122 | B8: 0 | C8: 0 | D8: 0 | E8: 0 | F8: 0 | G8: 0 | H8: 0 | I8: 0 | J8: 0 | K8: 0 | L8: 0 | M8: 0 | N8: 0 | O8: 0 | P8: 0 | Q8: 0 | R8: 0 | S8: 0 | T8: 0 | U8: 0 | V8: 0 | W8: 0 | X8: 0 | Y8: 0 | Z8: 0 | AA8: 0 | AB8: 0 | AC8: 0 | AD8: 0 | AE8: 0 | AF8: 0 | AG8: 0 | AH8: 0 | AI8: 0
A9: 123 | B9: 0 | C9: 0 | D9: 0 | E9: 0 | F9: 0 | G9: 0 | H9: 0 | I9: 0 | J9: 0 | K9: 0 | L9: 0 | M9: 0 | N9: 0 | O9: 0 | P9: 0 | Q9: 0 | R9: 0 | S9: 0 | T9: 0 | U9: 0 | V9: 0 | W9: 0 | X9: 0 | Y9: 0 | Z9: 0 | AA9: 0 | AB9: 0 | AC9: 0 | AD9: 0 | AE9: 0 | AF9: 0 | AG9: 0 | AH9: 0 | AI9: 0
A10: 124 | B10: 0 | C10: 0 | D10: 0 | E10: 0 | F10: 0 | G10: 0 | H10: 0 | I10: 0 | J10: 0 | K10: 0 | L10: 0 | M10: 0 | N10: 0 | O10: 0 | P10: 0 | Q10: 0 | R10: 0 | S10: 0 | T10: 0 | U10: 0 | V10: 0 | W10: 0 | X10: 0 | Y10: 0 | Z10: 0 | AA10: 0 | AB10: 0 | AC10: 0 | AD10: 0 | AE10: 0 | AF10: 0 | AG10: 0 | AH10: 0 | AI10: 0
A11: 125 | B11: 0 | C11: 0 | D11: 0 | E11: 0 | F11: 0 | G11: 0 | H11: 0 | I11: 0 | J11: 0 | K11: 0 | L11: 0 | M11: 0 | N11: 0 | O11: 0 | P11: 0 | Q11: 0 | R11: 0 | S11: 0 | T11: 0 | U11: 0 | V11: 0 | W11: 0 | X11: 0 | Y11: 0 | Z11: 0 | AA11: 0 | AB11: 0 | AC11: 0 | AD11: 0 | AE11: 0 | AF11: 0 | AG11: 0 | AH11: 0 | AI11: 0
A12: 126 | B12: 0 | C12: 0 | D12: 0 | E12: 0 | F12: 0 | G12: 0 | H12: 0 | I12: 0 | J12: 0 | K12: 0 | L12: 0 | M12: 0 | N12: 0 | O12: 0 | P12: 0 | Q12: 0 | R12: 0 | S12: 0 | T12: 0 | U12: 0 | V12: 0 | W12: 0 | X12: 0 | Y12: 0 | Z12: 0 | AA12: 0 | AB12: 0 | AC12: 0 | AD12: 0 | AE12: 0 | AF12: 0 | AG12: 0 | AH12: 0 | AI12: 0
A13: 127 | B13: 0 | C13: 0 | D13: 0 | E13: 0 | F13: 0 | G13: 0 | H13: 0 | I13: 0 | J13: 0 | K13: 0 | L13: 0 | M13: 0 | N13: 0 | O13: 0 | P13: 0 | Q13: 0 | R13: 0 | S13: 0 | T13: 0 | U13: 0 | V13: 0 | W13: 0 | X13: 0 | Y13: 0 | Z13: 0 | AA13: 0 | AB13: 0 | AC13: 0 | AD13: 0 | AE13: 0 | AF13: 0 | AG13: 0 | AH13: 0 | AI13: 0
A14: 128 | B14: 0 | C14: 0 | D14: 0 | E14: 0 | F14: 0 | G14: 0 | H14: 0 | I14: 0 | J14: 0 | K14: 0 | L14: 0 | M14: 0 | N14: 0 | O14: 0 | P14: 0 | Q14: 0 | R14: 0 | S14: 0 | T14: 0 | U14: 0 | V14: 0 | W14: 0 | X14: 0 | Y14: 0 | Z14: 0 | AA14: 0 | AB14: 0 | AC14: 0 | AD14: 0 | AE14: 0 | AF14: 0 | AG14: 0 | AH14: 0 | AI14: 0
A15: 129 | B15: 0 | C15: 0 | D15: 0 | E15: 0 | F15: 0 | G15: 0 | H15: 0 | I15: 0 | J15: 0 | K15: 0 | L15: 0 | M15: 0 | N15: 0 | O15: 0 | P15: 0 | Q15: 0 | R15: 0 | S15: 0 | T15: 0 | U15: 0 | V15: 0 | W15: 0 | X15: 0 | Y15: 0 | Z15: 0 | AA15: 0 | AB15: 0 | AC15: 0 | AD15: 0 | AE15: 0 | AF15: 0 | AG15: 0 | AH15: 0 | AI15: 0
A16: 130 | B16: 0.024816098 | C16: 0.04443311 | D16: 0 | E16: 0 | F16: 0 | G16: 0.036883877 | H16: 0.04235674 | I16: 0 | J16: 0 | K16: 0 | L16: 0 | M16: 0 | N16: 0 | O16: 0 | P16: 0 | Q16: 0 | R16: 0 | S16: 0 | T16: 0 | U16: 0 | V16: 0.0158472 | W16: 0 | X16: 0 | Y16: 0 | Z16: 0.034927718 | AA16: 0.069412564 | AB16: 1 | AC16: 0 | AD16: 0 | AE16: 0 | AF16: 0.015073546 | AG16: 0 | AH16: 0.03542188 | AI16: 0
A17: 131 | B17: 0.048857934 | C17: 0.087479908 | D17: 0 | E17: 0 | F17: 0 | G17: 0.072616979 | H17: 0.083391951 | I17: 0 | J17: 0 | K17: 0 | L17: 0 | M17: 0 | N17: 0 | O17: 0 | P17: 0 | Q17: 0 | R17: 0 | S17: 0 | T17: 0 | U17: 0 | V17: 0 | W17: 0 | X17: 0 | Y17: 0 | Z17: 0.068765693 | AA17: 0.13665946 | AB17: 2 | AC17: 0 | AD17: 0 | AE17: 0 | AF17: 0.029676799 | AG17: 0 | AH17: 0.069738598 | AI17: 0
A18: 132 | B18: 0.024428967 | C18: 0.043739954 | D18: 0 | E18: 0 | F18: 0 | G18: 0.036308489 | H18: 0.041695976 | I18: 0 | J18: 0 | K18: 0 | L18: 0 | M18: 0 | N18: 0 | O18: 0 | P18: 0 | Q18: 0 | R18: 0 | S18: 0 | T18: 0 | U18: 0 | V18: 0 | W18: 0 | X18: 0 | Y18: 0 | Z18: 0.034382847 | AA18: 0.068329729 | AB18: 1 | AC18: 0 | AD18: 0 | AE18: 0 | AF18: 0.014838399 | AG18: 0 | AH18: 0.034869299 | AI18: 0
... A120: 234 | B120: 9 | C120: 15.688774 | D120: 14.008996 | E120: 16.23681 | F120: 15.483867 | G120: 13.024971 | H120: 14.958048 | I120: 8.8641861 | J120: 12.213743 | K120: 8.3827294 | L120: 10.329112 | M120: 12.421134 | N120: 8.1240704 | O120: 11.916707 | P120: 13.711511 | Q120: 17.72178 | R120: 8.4620598 | S120: 14.481018 | T120: 16.85519 | U120: 11.627441 | V120: 5.5983932 | W120: 17.161918 | X120: 11.046241 | Y120: 17.936727 | Z120: 12.340389 | AA120: 24.524947 | AB120: 21.056551 | AC120: 18.966812 | AD120: 10.850759 | AE120: 17.691532 | AF120: 5.3268537 | AG120: 14.087177 | AH120: 12.518279 | AI120: 23.61928
A122: Subtotal | B122: =raw_data!B120 -> 46404 | C122: =raw_data!C120 -> 84383 | D122: =raw_data!D120 -> 61375 | E122: =raw_data!E120 -> 69737 | F122: =raw_data!F120 -> 76733 | G122: =raw_data!G120 -> 62110 | H122: =raw_data!H120 -> 72474 | I122: =raw_data!I120 -> 42463 | ... AI122: =raw_data!AI120 -> 118209
A123: Total | B123: =SUM(B7:B120) -> 47252.758 | C123: =SUM(C7:C120) -> 84606.074 | D123: =SUM(D7:D120) -> 75544.831 | E123: =SUM(E7:E120) -> 87555.862 | F123: =SUM(F7:F120) -> 83492.732 | G123: =SUM(G7:G120) -> 70231.416 | H123: =SUM(H7:H120) -> 80652.416 | I123: =SUM(I7:I120) -> 47793.328 | ... AI123: =SUM(AI7:AI120) -> 127255.64
A124: Global missfill | B124: =B123-B122 -> 848.7581 | C124: =C123-C122 -> 223.07446 | D124: =D123-D122 -> 14169.831 | E124: =E123-E122 -> 17818.862 | F124: =F123-F122 -> 6759.7321 | G124: =G123-G122 -> 8121.4158 | H124: =H123-H122 -> 8178.4157 | I124: =I123-I122 -> 5330.3283 | ... AI124: =AI123-AI122 -> 9046.6361
A125: % Missfill | B125: =B124/B123 -> 0.017962086 | C125: =C124/C123 -> 0.0026366246 | D125: =D124/D123 -> 0.1875685 | E125: =E124/E123 -> 0.20351421 | F125: =F124/F123 -> 0.080961922 | G125: =G124/G123 -> 0.11563793 | H125: =H124/H123 -> 0.10140323 | I125: =I124/I123 -> 0.11152871 | ... AI125: =AI124/AI123 -> 0.071090259 | AK125: =MIN(B125:AI125) -> 0.0026366246 | AL125: =MAX(B125:AI125) -> 0.25368698 | AM125: =AVERAGE(B125:AI125) -> 0.081076492

Sheet local_missfill
A1: Raw sockeye salmon counts; includes all count types, all maturity types.
A2: local missfill from R code | H2: Examples
A3: imputes a 10-year rolling imputation (prev & following 5 years) | H3: =(SUM(B16:L16)*SUM(G7:G120))/SUM(B7:L120) -> 0 | I3: =(SUM(Q92:AA92)*SUM(V7:V120))/SUM(Q7:AA120) -> 627.28346
A5: DAILY COUNTS:
A6: Date | B6: 1988 | C6: 1989 | D6: 1990 | E6: 1991 | F6: 1992 | G6: 1993 | H6: 1994 | I6: 1995 | J6: 1996 | K6: 1997 | L6: 1998 | M6: 1999 | N6: 2000 | O6: 2001 | P6: 2002 | Q6: 2003 | R6: 2004 | S6: 2005 | T6: 2006 | U6: 2007 | V6: 2008 | W6: 2009 | X6: 2010 | Y6: 2011 | Z6: 2012 | AA6: 2013 | AB6: 2014 | AC6: 2015 | AD6: 2016 | AE6: 2017 | AF6: 2018 | AG6: 2019 | AH6: 2020 | AI6: 2021
A7: 121 | B7: 0 | C7: 0 | D7: 0 | E7: 0 | F7: 0 | G7: 0 | H7: 0 | I7: 0 | J7: 0 | K7: 0 | L7: 0 | M7: 0 | N7: 0 | O7: 0 | P7: 0 | Q7: 0 | R7: 0 | S7: 0 | T7: 0 | U7: 0 | V7: 0 | W7: 0 | X7: 0 | Y7: 0 | Z7: 0 | AA7: 0 | AB7: 0 | AC7: 0 | AD7: 0 | AE7: 0 | AF7: 0 | AG7: 0 | AH7: 0 | AI7: 0
A8: 122 | B8: 0 | C8: 0 | D8: 0 | E8: 0 | F8: 0 | G8: 0 | H8: 0 | I8: 0 | J8: 0 | K8: 0 | L8: 0 | M8: 0 | N8: 0 | O8: 0 | P8: 0 | Q8: 0 | R8: 0 | S8: 0 | T8: 0 | U8: 0 | V8: 0 | W8: 0 | X8: 0 | Y8: 0 | Z8: 0 | AA8: 0 | AB8: 0 | AC8: 0 | AD8: 0 | AE8: 0 | AF8: 0 | AG8: 0 | AH8: 0 | AI8: 0
A9: 123 | B9: 0 | C9: 0 | D9: 0 | E9: 0 | F9: 0 | G9: 0 | H9: 0 | I9: 0 | J9: 0 | K9: 0 | L9: 0 | M9: 0 | N9: 0 | O9: 0 | P9: 0 | Q9: 0 | R9: 0 | S9: 0 | T9: 0 | U9: 0 | V9: 0 | W9: 0 | X9: 0 | Y9: 0 | Z9: 0 | AA9: 0 | AB9: 0 | AC9: 0 | AD9: 0 | AE9: 0 | AF9: 0 | AG9: 0 | AH9: 0 | AI9: 0
A10: 124 | B10: 0 | C10: 0 | D10: 0 | E10: 0 | F10: 0 | G10: 0 | H10: 0 | I10: 0 | J10: 0 | K10: 0 | L10: 0 | M10: 0 | N10: 0 | O10: 0 | P10: 0 | Q10: 0 | R10: 0 | S10: 0 | T10: 0 | U10: 0 | V10: 0 | W10: 0 | X10: 0 | Y10: 0 | Z10: 0 | AA10: 0 | AB10: 0 | AC10: 0 | AD10: 0 | AE10: 0 | AF10: 0 | AG10: 0 | AH10: 0 | AI10: 0
A11: 125 | B11: 0 | C11: 0 | D11: 0 | E11: 0 | F11: 0 | G11: 0 | H11: 0 | I11: 0 | J11: 0 | K11: 0 | L11: 0 | M11: 0 | N11: 0 | O11: 0 | P11: 0 | Q11: 0 | R11: 0 | S11: 0 | T11: 0 | U11: 0 | V11: 0 | W11: 0 | X11: 0 | Y11: 0 | Z11: 0 | AA11: 0 | AB11: 0 | AC11: 0 | AD11: 0 | AE11: 0 | AF11: 0 | AG11: 0 | AH11: 0 | AI11: 0
A12: 126 | B12: 0 | C12: 0 | D12: 0 | E12: 0 | F12: 0 | G12: 0 | H12: 0 | I12: 0 | J12: 0 | K12: 0 | L12: 0 | M12: 0 | N12: 0 | O12: 0 | P12: 0 | Q12: 0 | R12: 0 | S12: 0 | T12: 0 | U12: 0 | V12: 0 | W12: 0 | X12: 0 | Y12: 0 | Z12: 0 | AA12: 0 | AB12: 0 | AC12: 0 | AD12: 0 | AE12: 0 | AF12: 0 | AG12: 0 | AH12: 0 | AI12: 0
A13: 127 | B13: 0 | C13: 0 | D13: 0 | E13: 0 | F13: 0 | G13: 0 | H13: 0 | I13: 0 | J13: 0 | K13: 0 | L13: 0 | M13: 0 | N13: 0 | O13: 0 | P13: 0 | Q13: 0 | R13: 0 | S13: 0 | T13: 0 | U13: 0 | V13: 0 | W13: 0 | X13: 0 | Y13: 0 | Z13: 0 | AA13: 0 | AB13: 0 | AC13: 0 | AD13: 0 | AE13: 0 | AF13: 0 | AG13: 0 | AH13: 0 | AI13: 0
A14: 128 | B14: 0 | C14: 0 | D14: 0 | E14: 0 | F14: 0 | G14: 0 | H14: 0 | I14: 0 | J14: 0 | K14: 0 | L14: 0 | M14: 0 | N14: 0 | O14: 0 | P14: 0 | Q14: 0 | R14: 0 | S14: 0 | T14: 0 | U14: 0 | V14: 0 | W14: 0 | X14: 0 | Y14: 0 | Z14: 0 | AA14: 0 | AB14: 0 | AC14: 0 | AD14: 0 | AE14: 0 | AF14: 0 | AG14: 0 | AH14: 0 | AI14: 0
A15: 129 | B15: 0 | C15: 0 | D15: 0 | E15: 0 | F15: 0 | G15: 0 | H15: 0 | I15: 0 | J15: 0 | K15: 0 | L15: 0 | M15: 0 | N15: 0 | O15: 0 | P15: 0 | Q15: 0 | R15: 0 | S15: 0 | T15: 0 | U15: 0 | V15: 0 | W15: 0 | X15: 0 | Y15: 0 | Z15: 0 | AA15: 0 | AB15: 0 | AC15: 0 | AD15: 0 | AE15: 0 | AF15: 0 | AG15: 0 | AH15: 0 | AI15: 0
A16: 130 | B16: 0 | C16: 0 | D16: 0 | E16: 0 | F16: 0 | G16: 0 | H16: 0 | I16: 0 | J16: 0 | K16: 0 | L16: 0 | M16: 0 | N16: 0 | O16: 0 | P16: 0 | Q16: 0 | R16: 0 | S16: 0 | T16: 0 | U16: 0 | V16: 0.010985719 | W16: 0 | X16: 0 | Y16: 0 | Z16: 0.095840931 | AA16: 0.20435248 | AB16: 1 | AC16: 0 | AD16: 0 | AE16: 0 | AF16: 0.045181769 | AG16: 0 | AH16: 0.0062838543 | AI16: 0
A17: 131 | B17: 0 | C17: 0 | D17: 0 | E17: 0 | F17: 0 | G17: 0 | H17: 0 | I17: 0 | J17: 0 | K17: 0 | L17: 0 | M17: 0 | N17: 0 | O17: 0 | P17: 0 | Q17: 0 | R17: 0 | S17: 0 | T17: 0 | U17: 0 | V17: 0 | W17: 0 | X17: 0 | Y17: 0 | Z17: 0.18961063 | AA17: 0.4044115 | AB17: 2 | AC17: 0 | AD17: 0 | AE17: 0 | AF17: 0.090202466 | AG17: 0 | AH17: 0.012545307 | AI17: 0
A18: 132 | B18: 0 | C18: 0 | D18: 0 | E18: 0 | F18: 0 | G18: 0 | H18: 0 | I18: 0 | J18: 0 | K18: 0 | L18: 0 | M18: 0 | N18: 0 | O18: 0 | P18: 0 | Q18: 0 | R18: 0 | S18: 0 | T18: 0 | U18: 0 | V18: 0 | W18: 0 | X18: 0 | Y18: 0 | Z18: 0.094805313 | AA18: 0.20220575 | AB18: 1 | AC18: 0 | AD18: 0 | AE18: 0 | AF18: 0.045101233 | AG18: 0 | AH18: 0.0062726535 | AI18: 0
... A120: 234 | B120: 9 | C120: 13.298383 | D120: 11.374735 | E120: 13.150018 | F120: 12.460869 | G120: 10.161611 | H120: 11.58547 | I120: 6.8163179 | J120: 9.2767486 | K120: 6.2474265 | L120: 7.480792 | M120: 8.8879711 | N120: 5.7565394 | O120: 8.2930536 | P120: 9.3983364 | Q120: 12.033289 | R120: 5.6722376 | S120: 9.4870097 | T120: 10.769794 | U120: 7.3799415 | V120: 3.5223049 | W120: 10.79015 | X120: 6.8977158 | Y120: 11.110098 | Z120: 7.5476989 | AA120: 14.934577 | AB120: 12.868011 | AC120: 11.499123 | AD120: 6.5219954 | AE120: 10.639053 | AF120: 3.2183082 | AG120: 8.4515369 | AH120: 7.5375563 | AI120: 14.021861
A122: Subtotal | B122: =raw_data!B120 -> 46404 | C122: =raw_data!C120 -> 84383 | D122: =raw_data!D120 -> 61375 | E122: =raw_data!E120 -> 69737 | F122: =raw_data!F120 -> 76733 | G122: =raw_data!G120 -> 62110 | H122: =raw_data!H120 -> 72474 | I122: =raw_data!I120 -> 42463 | ... AI122: =raw_data!AI120 -> 118209
A123: Total | B123: =SUM(B7:B120) -> 46461.904 | C123: =SUM(C7:C120) -> 84566.288 | D123: =SUM(D7:D120) -> 72752.491 | E123: =SUM(E7:E120) -> 84839.027 | F123: =SUM(F7:F120) -> 80908.638 | G123: =SUM(G7:G120) -> 66564.961 | H123: =SUM(H7:H120) -> 78081.875 | I123: =SUM(I7:I120) -> 46627.031 | ... AI123: =SUM(AI7:AI120) -> 127823.03
A124: local missfill | B124: =B123-B122 -> 57.903515 | C124: =C123-C122 -> 183.28836 | D124: =D123-D122 -> 11377.491 | E124: =E123-E122 -> 15102.027 | F124: =F123-F122 -> 4175.6378 | G124: =G123-G122 -> 4454.9609 | H124: =H123-H122 -> 5607.8753 | I124: =I123-I122 -> 4164.0313 | ... AI124: =AI123-AI122 -> 9614.0253
A125: % Missfill | B125: =B124/B123 -> 0.0012462579 | C125: =C124/C123 -> 0.0021673927 | D125: =D124/D123 -> 0.15638628 | E125: =E124/E123 -> 0.17800801 | F125: =F124/F123 -> 0.051609296 | G125: =G124/G123 -> 0.066926516 | H125: =H124/H123 -> 0.071820448 | I125: =I124/I123 -> 0.089305092 | ... AI125: =AI124/AI123 -> 0.075213564 | AK125: =MIN(B125:AI125) -> 0.0012462579 | AL125: =MAX(B125:AI125) -> 0.26048787 | AM125: =AVERAGE(B125:AI125) -> 0.081911363
